<?xml version='1.0'?>
<sdf version='1.6'>
  <model name="Stoupento">
    <static>false</static>

              <link name='right_wheel'>
            <pose>0 0.16 0.07  1.5707963267948966192313216916398\0 0</pose>

          <inertial>
          <mass>0.3</mass>
                  <inertia> 
          <ixx>0.00039</ixx>   <ixy>0.0</ixy>    <ixz>0.0</ixz>        
          <iyy>0.00039</iyy>     <iyz>0</iyz>   <izz> 0.000735</izz>      
        </inertia>

          </inertial>



            <collision name='collision_wr'>
              <geometry>
                <cylinder>
                 <radius>0.07</radius> <length>0.03</length>
                </cylinder>
              </geometry>
         <surface>
            <friction>
              <ode>
                <mu>0.8</mu>
                <mu2>0.8</mu2>
              </ode>
            </friction>
          </surface>
            </collision>

            <visual name='visual_wr'>
              <geometry>
                <cylinder>
                 <radius>0.07</radius> <length>0.03</length>
                </cylinder>
              </geometry>
             <material> 
          <script>
            <uri>file://wheel.material</uri>
            <name>WheelTexture</name>
          </script>
        </material> 
            </visual>

                                          <sensor type="imu" name="rightwheel_imu">
          <imu>

          </imu>
          <always_on>1</always_on>
          <visualize>true</visualize>
          <topic>rightwheellMU</topic>
        </sensor>
          </link>

                        <link name='left_wheel'>
            <pose>0 -0.16 0.07 1.5707963267948966192313216916398 0 0</pose>

          <inertial>
          <mass>0.3</mass>
                  <inertia> 
          <ixx>0.00039</ixx>   <ixy>0.0</ixy>    <ixz>0.0</ixz>        
          <iyy>0.00039</iyy>     <iyz>0</iyz>   <izz> 0.000735</izz>      
        </inertia>

          </inertial>



            <collision name='collision_wl'>
              <geometry>
                <cylinder>
                 <radius>0.07</radius> <length>0.03</length>
                </cylinder>
              </geometry>
          <surface>
            <friction>
              <ode>
                <mu>0.8</mu>
                <mu2>0.8</mu2>
              </ode>
            </friction>
          </surface>
            </collision>

            <visual name='visual_wl'>
              <geometry>
                <cylinder>
                 <radius>0.07</radius> <length>0.03</length>
                </cylinder>
              </geometry>
                           <material> 
          <script>
            <uri>file://wheel.material</uri>
            <name>WheelTexture</name>
          </script>
        </material>
            </visual>

                                        <sensor type="imu" name="leftwheel_imu">
          <imu>

          </imu>
          <always_on>1</always_on>
          <visualize>true</visualize>
          <topic>leftwheelIMU</topic>
        </sensor>
          </link>



                                  <link name='right_link1'>
            <pose>0.084852813742385702928101323452582 0.14 0.1548528137423856865240168190212 0 -0.78539816339744830961566084581988 0 </pose>

          <inertial>
          <mass>0.2</mass>
                  <inertia> 
          <ixx>0.000016666666666666666666666666666667</ixx>   <ixy>0.0</ixy>    <ixz>0.0</ixz>        
          <iyy>0.000975</iyy>     <iyz>0</iyz>   <izz> 0.00096166666666666665921892054313957</izz>      
        </inertia>

          </inertial>



            <collision name='collision_l1r'>
              <geometry>
                <box>
                 <size>0.24 0.01 0.03 </size>
                </box>
              </geometry>
            </collision>

            <visual name='visual_l1r'>
              <geometry>
                <box>
                 <size>0.24 0.01 0.03 </size>
                </box>
              </geometry>
            </visual>
          </link>

                                            <link name='left_link1'>
            <pose>0.084852813742385702928101323452582 -0.14 0.1548528137423856865240168190212 0 -0.78539816339744830961566084581988  </pose>

          <inertial>
          <mass>0.2</mass>
                <inertia> 
          <ixx>0.000016666666666666666666666666666667</ixx>   <ixy>0.0</ixy>    <ixz>0.0</ixz>        
          <iyy>0.000975</iyy>     <iyz>0</iyz>   <izz> 0.00096166666666666665921892054313957</izz>      
        </inertia>

          </inertial>



            <collision name='collision_l1l'>
              <geometry>
                <box>
                 <size>0.24 0.01 0.03 </size>
                </box>
              </geometry>
            </collision>

            <visual name='visual_l1l'>
              <geometry>
                <box>
                 <size>0.24 0.01 0.03 </size>
                </box>
              </geometry>
            </visual>
          </link>


                                            <link name='right_link2'>
            <pose>0.056506396484663795609648673234915 0.13 0.25704116512636943081560048085521 0 -2.5465534245966794379967268469045 0</pose>

          <inertial>
          <mass>0.2</mass>
                  <inertia> 
          <ixx>0.000016666666666666666666666666666667</ixx>   <ixy>0.0</ixy>    <ixz>0.0</ixz>        
          <iyy>0.00060406666666666664067264491677633</iyy>     <iyz>0</iyz>   <izz> 0.00059073333333333334464743114011753</izz>      
        </inertia>

          </inertial>



            <collision name='collision_l2r'>
              <geometry>
                <box>
                 <size>0.188 0.01 0.03 </size>
                </box>
              </geometry>
            </collision>

            <visual name='visual_l2r'>
              <geometry>
                <box>
                 <size>0.188 0.01 0.03 </size>
                </box>
              </geometry>
            </visual>
          </link>

                                                 <link name='left_link2'>
            <pose>0.056506396484663795609648673234915 -0.13 0.25704116512636943081560048085521 0 -2.5465534245966794379967268469045 0</pose>

          <inertial>
          <mass>0.2</mass>
                  <inertia> 
          <ixx>0.000016666666666666666666666666666667</ixx>   <ixy>0.0</ixy>    <ixz>0.0</ixz>        
          <iyy>0.00060406666666666664067264491677633</iyy>     <iyz>0</iyz>   <izz> 0.00059073333333333334464743114011753</izz>      
        </inertia>

          </inertial>



            <collision name='collision_l2l'>
              <geometry>
                <box>
                 <size>0.188 0.01 0.03 </size>
                </box>
              </geometry>
            </collision>

            <visual name='visual_l2l'>
              <geometry>
                <box>
                 <size>0.188 0.01 0.03 </size>
                </box>
              </geometry>
            </visual>
          </link>


          
                                            <link name='right_link4'>
            <pose>0.10401162246961447033211101143024 0.13 0.31039188997663424984807534201536 0 -2.3196054032563253599619201850146 0</pose>

          <inertial>
          <mass>0.1</mass>
                  <inertia> 
  <ixx>0.0000083333333333333337326811335321608</ixx>   <ixy>0.0</ixy>    <ixz>0.0</ixz>        
          <iyy>0.00031790833333333336739590091468699</iyy>     <iyz>0</iyz>   <izz> 0.00031124166666666671938329402635759</izz>         
        </inertia>

          </inertial>



            <collision name='collision_l4r'>
              <geometry>
                <box>
                 <size>0.193 0.01 0.03 </size>
                </box>
              </geometry>
            </collision>

            <visual name='visual_l4r'>
              <geometry>
                <box>
                 <size>0.193 0.01 0.03 </size>
                </box>
              </geometry>
            </visual>
          </link>


                                       <link name='left_link4'>
            <pose>0.10401162246961447033211101143024 -0.13 0.31039188997663424984807534201536 0 -2.3196054032563253599619201850146 0</pose>

          <inertial>
          <mass>0.1</mass>
                  <inertia> 
 <ixx>0.0000083333333333333337326811335321608</ixx>   <ixy>0.0</ixy>    <ixz>0.0</ixz>        
          <iyy>0.00031790833333333336739590091468699</iyy>     <iyz>0</iyz>   <izz> 0.00031124166666666671938329402635759</izz>    
        </inertia>

          </inertial>



            <collision name='collision_l4l'>
              <geometry>
                <box>
                 <size>0.193 0.01 0.03 </size>
                </box>
              </geometry>
            </collision>

            <visual name='visual_l4l'>
              <geometry>
                <box>
                 <size>0.193 0.01 0.03 </size>
                </box>
              </geometry>
            </visual>
          </link>

                                                 <link name='body'>
            <pose>-0.025782002861580825825438267884238 0 0.35953411361073350782646684820065 0 -1.6598039534002866357553784837364 0</pose>

          <inertial>
          <mass>3</mass>
                 <inertia> 
          <ixx>0.023725</ixx>   <ixy>0.0</ixy>    <ixz>0.0</ixz>        
          <iyy>0.023725</iyy>     <iyz>0</iyz>   <izz> 0.03125</izz>      
        </inertia>

          </inertial>



            <collision name='collision_b'>
              <geometry>
                <box>
                 <size>0.25 0.25 0.18 </size>
                </box>
              </geometry>
            </collision>

            <visual name='visual_b'>
              <geometry>
                <box>
                 <size>0.25 0.25 0.18 </size>
                </box>
              </geometry>
            </visual>


                  <sensor type="imu" name="body_imu">
          <imu>

          </imu>
          <always_on>1</always_on>
          <visualize>true</visualize>
          <topic>bodyIMU</topic>
        </sensor>



          </link>

                <joint type="revolute" name="wheel_link1R">
        <pose>0 0 0 0 0 0</pose>
        <child>right_wheel</child>
        <parent>right_link1</parent>
        <axis>
         <dynamics>
          <damping> 0.01 </damping>
          </dynamics>
          <xyz>0 0 1</xyz>
        </axis>
      </joint>

                     <joint type="revolute" name="wheel_link1L">
        <pose>0 0 0 0 0 0</pose>
        <child>left_wheel</child>
        <parent>left_link1</parent>
        <axis>
         <dynamics>
          <damping> 0.01 </damping>
          </dynamics>
          <xyz>0 0 1</xyz>
        </axis>
      </joint>

                      <joint type="revolute" name="link1_link2R">
        <pose> 0.07 -0.005 0 0 0</pose>
        <child>right_link1</child>
        <parent>right_link2</parent>
        <axis>
          <xyz>0 1 0</xyz>
                  <dynamics> 
                  <damping> 0.01 </damping>
        <spring_reference>
        -10.264
        </spring_reference>
        <spring_stiffness>
        0.247
        </spring_stiffness>
        </dynamics>
        </axis>
      </joint>

                     <joint type="revolute" name="link1_link2L">
        <pose>0.07 0.005 0 0 0 0</pose>
        <child>left_link1</child>
        <parent>left_link2</parent>
        <axis>
          <xyz>0 1 0</xyz>
                  <dynamics> 
                  <damping> 0.01 </damping>
        <spring_reference>
        -10.264
        </spring_reference>
        <spring_stiffness>
      0.247
        </spring_stiffness>
        </dynamics>
        </axis>
      </joint>

                            <joint type="revolute" name="link1_link4R">
        <pose> 0.12 -0.005 0 0 0</pose>
        <child>right_link1</child>
        <parent>right_link4</parent>
        <axis>
         <dynamics>
          <damping> 0.01 </damping>
          </dynamics>
          <xyz>0 1 0</xyz>
        </axis>
      </joint>

                     <joint type="revolute" name="link1_link4L">
        <pose>0.12 0.005 0 0 0 0</pose>
        <child>left_link1</child>
        <parent>left_link4</parent>
        <axis>
         <dynamics>
          <damping> 0.01 </damping>
          </dynamics>
          <xyz>0 1 0</xyz>
        </axis>
      </joint>

                                  <joint type="revolute" name="link2_bodyR">
        <pose> 0.0940 -0.005 0 0 0</pose>
        <child>right_link2</child>
        <parent>body</parent>
        <axis>
         <dynamics>
          <damping> 0.01 </damping>
          </dynamics>
          <xyz>0 1 0</xyz>
        </axis>
      </joint>

                                      <joint type="revolute" name="link2_bodyL">
        <pose> 0.0940 0.005 0 0 0</pose>
        <child>left_link2</child>
        <parent>body</parent>
        <axis>
         <dynamics>
          <damping> 0.01 </damping>
          </dynamics>
          <xyz>0 1 0</xyz>
        </axis>
      </joint>

                                        <joint type="revolute" name="link4_bodyR">
        <pose> 0.0965 -0.005 0 0 0</pose>
        <child>right_link4</child>
        <parent>body</parent>
        <axis>
         <dynamics>
          <damping> 0.01 </damping>
          </dynamics>
          <xyz>0 1 0</xyz>
        </axis>
      </joint>

                                      <joint type="revolute" name="link4_bodyL">
        <pose> 0.0965 0.005 0 0 0</pose>
        <child>left_link4</child>
        <parent>body</parent>
        <axis>
         <dynamics>
          <damping> 0.01 </damping>
          </dynamics>
          <xyz>0 1 0</xyz>
        </axis>
      </joint>

   <plugin name="encoderPlug" filename="/home/kollaada/stoupentoPlugin/build/libstoupentoPlugin.so"> 
  <joint1L>wheel_link1L</joint1L> <joint2L>link1_link2L</joint2L> <joint3L>link2_bodyL</joint3L> <joint4L>link1_link4L</joint4L>
  <joint1R>wheel_link1R</joint1R> <joint2R>link1_link2R</joint2R> <joint3R>link2_bodyR</joint3R> <joint4R>link1_link4R</joint4R>
  <wheelL>left_wheel</wheelL> <wheelR>right_wheel</wheelR>
   </plugin>




  </model>
</sdf>